<?xml version="1.0" ?>
<!-- =================================================================================== -->
<!-- |    This document was autogenerated by xacro from /mnt/c/Users/ricard.marsal/Documents/GitHub/UniLuFP/ros_ws/install/pingu_description/share/pingu_description/urdf/pingu_v3.urdf.xacro | -->
<!-- |    EDITING THIS FILE BY HAND IS NOT RECOMMENDED                                 | -->
<!-- =================================================================================== -->
<robot name="pingu_v3">
 <material name="levion_black">
  <color rgba="0.3 0.3 0.3 1.0"/>
 </material>
 <material name="orange">
  <color rgba="1.0 0.5 0.0 1.0"/>
 </material>
 <material name="elec_blue">
  <color rgba="0.0 0.0 1.0 1.0"/>
 </material>
 <!-- World Link -->
 <link name="world"/>
 <!-- Joins and Links for Floating -->
 <link name="anchor_link"/>
 <joint name="anchor_joint" type="fixed">
  <origin rpy="0 0 0" xyz="0 0 0.05"/>
  <parent link="world"/>
  <child link="anchor_link"/>
 </joint>
 <link name="x_lock_link"/>
 <joint name="x_lock_joint" type="prismatic">
  <origin rpy="0 0 0" xyz="0 0 0"/>
  <parent link="anchor_link"/>
  <child link="x_lock_link"/>
  <axis xyz="1 0 0"/>
  <limit effort="10.0" lower="-10" upper="10" velocity="10"/>
 </joint>
 <link name="y_lock_link"/>
 <joint name="y_lock_joint" type="prismatic">
  <origin rpy="0 0 0" xyz="0 0 0"/>
  <parent link="x_lock_link"/>
  <child link="y_lock_link"/>
  <axis xyz="0 1 0"/>
  <limit effort="10.0" lower="-10" upper="10" velocity="10"/>
 </joint>
 <!-- Base Join and Link-->
 <link name="base_link">
  <visual>
   <geometry>
    <mesh filename="package://pingu_description/mesh/base_link.stl" scale="0.001 0.001 0.001"/>
   </geometry>
   <material name="levion_black"/>
   <origin rpy="0 0 -1.57079632675" xyz="0 0 0"/>
  </visual>
  <collision>
   <geometry>
    <mesh filename="package://pingu_description/mesh/base_link.stl" scale="0.001 0.001 0.001"/>
   </geometry>
   <origin rpy="0 0 0" xyz="0 0 0"/>
   <!-- 0 0 0.3276 for box -->
  </collision>
  <inertial>
   <mass value="23.0"/>
   <origin rpy="0 0 0" xyz="0 0 0.3276"/>
   <inertia ixx="0.7" ixy="0" ixz="0" iyy="0.7" iyz="0" izz="0.5"/>
  </inertial>
 </link>
 <joint name="base_joint" type="revolute">
  <origin rpy="0 0 0" xyz="0 0 0"/>
  <parent link="y_lock_link"/>
  <child link="base_link"/>
  <axis xyz="0 0 1"/>
  <limit effort="10.0" lower="-10" upper="10" velocity="10"/>
  <!-- <dynamics damping="0.5" friction="0.0"/> -->
 </joint>
 <!-- Base Link -->
 <link name="rw_base"/>
 <joint name="rw_base_joint" type="fixed">
  <origin rpy="0 0 0" xyz="0 0 .2875"/>
  <parent link="base_link"/>
  <child link="rw_base"/>
 </joint>
 <!-- Middle Link -->
 <link name="rw_rotor">
  <visual>
   <origin rpy="0 0 0" xyz="0 0 0"/>
   <geometry>
    <cylinder length="0.008" radius="0.1"/>
   </geometry>
   <material name="orange"/>
  </visual>
  <inertial>
   <origin rpy="0 0 0" xyz="0 0 0"/>
   <mass value="2.0"/>
   <inertia ixx="0.06" ixy="0.0" ixz="0.0" iyy="0.06" iyz="0.0" izz="0.1"/>
  </inertial>
 </link>
 <joint name="rw_revolute_joint" type="revolute">
  <parent link="rw_base"/>
  <child link="rw_rotor"/>
  <origin rpy="0 0 0" xyz="0 0 0.05"/>
  <axis xyz="0 0 1"/>
  <limit effort="10.0" lower="-1e9" upper="1e9" velocity="100"/>
  <dynamics damping="0.5" friction="0.5"/>
 </joint>
 <!-- Middle Fix Link -->
 <!-- <link name="${prefix}rw_fixed_rotor"></link>

  <joint name="${prefix}rw_fixed_joint" type="fixed">
    <parent link="${prefix}rw_base"/>
    <child link="${prefix}rw_fixed_rotor"/>
    <origin xyz="0 0 0.05" rpy="0 0 0"/>
    <axis xyz="0 0 1"/>
    <limit effort="10.0" lower="-1e9" upper="1e9" velocity="100"/>
    <dynamics damping="0.5" friction="0.5"/>
  </joint> -->
 <!-- Left Arm description -->
 <!-- <xacro:levion_arm parent="base_link" prefix="$(arg prefix)" left_right="left">
    <origin xyz="0.26 0 .3475" rpy="0 0 0" />
  </xacro:levion_arm> -->
 <!-- Right Arm description -->
 <!-- <xacro:levion_arm parent="base_link" prefix="$(arg prefix)" left_right="right">
    <origin xyz="0 -0.26 .3475" rpy="0 0 ${-PI/2}" />
  </xacro:levion_arm> -->
 <!-- Thruster Link -->
 <link name="thruster_1_link">
  <visual>
   <origin rpy="0 0 0" xyz="0 0 0"/>
   <geometry>
    <cylinder length="0.055" radius="0.006"/>
   </geometry>
   <material name="elec_blue"/>
  </visual>
  <parent link="base_link"/>
  <origin rpy="1.57079632675 0 -0.785398163375" xyz="-0.168 0.168 0.295"/>
 </link>
 <joint name="thruster_1_joint" type="fixed">
  <parent link="base_link"/>
  <child link="thruster_1_link"/>
  <origin rpy="1.57079632675 0 -0.785398163375" xyz="-0.168 0.168 0.295"/>
 </joint>
 <!-- Thruster Link -->
 <link name="thruster_2_link">
  <visual>
   <origin rpy="0 0 0" xyz="0 0 0"/>
   <geometry>
    <cylinder length="0.055" radius="0.006"/>
   </geometry>
   <material name="elec_blue"/>
  </visual>
  <parent link="base_link"/>
  <origin rpy="-1.57079632675 0 0.785398163375" xyz="-0.168 0.168 0.305"/>
 </link>
 <joint name="thruster_2_joint" type="fixed">
  <parent link="base_link"/>
  <child link="thruster_2_link"/>
  <origin rpy="-1.57079632675 0 0.785398163375" xyz="-0.168 0.168 0.305"/>
 </joint>
 <!-- Thruster Link -->
 <link name="thruster_3_link">
  <visual>
   <origin rpy="0 0 0" xyz="0 0 0"/>
   <geometry>
    <cylinder length="0.055" radius="0.006"/>
   </geometry>
   <material name="elec_blue"/>
  </visual>
  <parent link="base_link"/>
  <origin rpy="-1.57079632675 0 -0.785398163375" xyz="0.168 0.168 0.295"/>
 </link>
 <joint name="thruster_3_joint" type="fixed">
  <parent link="base_link"/>
  <child link="thruster_3_link"/>
  <origin rpy="-1.57079632675 0 -0.785398163375" xyz="0.168 0.168 0.295"/>
 </joint>
 <!-- Thruster Link -->
 <link name="thruster_4_link">
  <visual>
   <origin rpy="0 0 0" xyz="0 0 0"/>
   <geometry>
    <cylinder length="0.055" radius="0.006"/>
   </geometry>
   <material name="elec_blue"/>
  </visual>
  <parent link="base_link"/>
  <origin rpy="1.57079632675 0 0.785398163375" xyz="0.168 0.168 0.305"/>
 </link>
 <joint name="thruster_4_joint" type="fixed">
  <parent link="base_link"/>
  <child link="thruster_4_link"/>
  <origin rpy="1.57079632675 0 0.785398163375" xyz="0.168 0.168 0.305"/>
 </joint>
 <!-- Thruster Link -->
 <link name="thruster_5_link">
  <visual>
   <origin rpy="0 0 0" xyz="0 0 0"/>
   <geometry>
    <cylinder length="0.055" radius="0.006"/>
   </geometry>
   <material name="elec_blue"/>
  </visual>
  <parent link="base_link"/>
  <origin rpy="-1.57079632675 0 0.785398163375" xyz="0.168 -0.168 0.305"/>
 </link>
 <joint name="thruster_5_joint" type="fixed">
  <parent link="base_link"/>
  <child link="thruster_5_link"/>
  <origin rpy="-1.57079632675 0 0.785398163375" xyz="0.168 -0.168 0.305"/>
 </joint>
 <!-- Thruster Link -->
 <link name="thruster_6_link">
  <visual>
   <origin rpy="0 0 0" xyz="0 0 0"/>
   <geometry>
    <cylinder length="0.055" radius="0.006"/>
   </geometry>
   <material name="elec_blue"/>
  </visual>
  <parent link="base_link"/>
  <origin rpy="1.57079632675 0 -0.785398163375" xyz="0.168 -0.168 0.295"/>
 </link>
 <joint name="thruster_6_joint" type="fixed">
  <parent link="base_link"/>
  <child link="thruster_6_link"/>
  <origin rpy="1.57079632675 0 -0.785398163375" xyz="0.168 -0.168 0.295"/>
 </joint>
 <!-- Thruster Link -->
 <link name="thruster_7_link">
  <visual>
   <origin rpy="0 0 0" xyz="0 0 0"/>
   <geometry>
    <cylinder length="0.055" radius="0.006"/>
   </geometry>
   <material name="elec_blue"/>
  </visual>
  <parent link="base_link"/>
  <origin rpy="1.57079632675 0 0.785398163375" xyz="-0.168 -0.168 0.305"/>
 </link>
 <joint name="thruster_7_joint" type="fixed">
  <parent link="base_link"/>
  <child link="thruster_7_link"/>
  <origin rpy="1.57079632675 0 0.785398163375" xyz="-0.168 -0.168 0.305"/>
 </joint>
 <!-- Thruster Link -->
 <link name="thruster_8_link">
  <visual>
   <origin rpy="0 0 0" xyz="0 0 0"/>
   <geometry>
    <cylinder length="0.055" radius="0.006"/>
   </geometry>
   <material name="elec_blue"/>
  </visual>
  <parent link="base_link"/>
  <origin rpy="-1.57079632675 0 -0.785398163375" xyz="-0.168 -0.168 0.295"/>
 </link>
 <joint name="thruster_8_joint" type="fixed">
  <parent link="base_link"/>
  <child link="thruster_8_link"/>
  <origin rpy="-1.57079632675 0 -0.785398163375" xyz="-0.168 -0.168 0.295"/>
 </joint>
</robot>
