<?xml version="1.0" ?>
<!-- =================================================================================== -->
<!-- |    This document was autogenerated by xacro from /mnt/c/Users/ricard.marsal/Documents/GitHub/UniLuFP/ros_ws/install/pingu_description/share/pingu_description/urdf/pingu_v3.urdf.xacro | -->
<!-- |    EDITING THIS FILE BY HAND IS NOT RECOMMENDED                                 | -->
<!-- =================================================================================== -->
<robot name="pingu_v3">
 <material name="levion_black">
  <color rgba="0.3 0.3 0.3 1.0"/>
 </material>
 <material name="orange">
  <color rgba="1.0 0.5 0.0 1.0"/>
 </material>
 <!-- Joins and Links for Floating -->
 <link name="anchor_link">
  <visual>
   <geometry>
    <box size="0.001 0.001 0.001"/>
   </geometry>
   <material name="levion_black"/>
   <origin rpy="0 0 0" xyz="0 0 0"/>
  </visual>
  <collision>
   <geometry>
    <box size="0.001 0.001 0.001"/>
   </geometry>
   <origin rpy="0 0 0" xyz="0 0 0"/>
  </collision>
  <inertial>
   <mass value="0.0001"/>
   <origin rpy="0 0 0" xyz="0 0 0"/>
   <inertia ixx="0.0001" ixy="0" ixz="0" iyy="0.0001" iyz="0" izz="0.0001"/>
  </inertial>
 </link>
 <joint name="anchor_joint" type="fixed">
  <origin rpy="0 0 0" xyz="0 0 0.2"/>
  <parent link="robot"/>
  <child link="anchor_link"/>
 </joint>
 <link name="x_lock_link">
  <visual>
   <geometry>
    <box size="0.001 0.001 0.001"/>
   </geometry>
   <material name="levion_black"/>
   <origin rpy="0 0 0" xyz="0 0 0"/>
  </visual>
  <collision>
   <geometry>
    <box size="0.001 0.001 0.001"/>
   </geometry>
   <origin rpy="0 0 0" xyz="0 0 0"/>
  </collision>
  <inertial>
   <mass value="0.0001"/>
   <origin rpy="0 0 0" xyz="0 0 0"/>
   <inertia ixx="0.0001" ixy="0" ixz="0" iyy="0.0001" iyz="0" izz="0.0001"/>
  </inertial>
 </link>
 <joint name="x_lock_joint" type="prismatic">
  <origin rpy="0 0 0" xyz="0 0 0"/>
  <parent link="anchor_link"/>
  <child link="x_lock_link"/>
  <axis xyz="1 0 0"/>
  <limit effort="10.0" lower="-10" upper="10" velocity="10"/>
 </joint>
 <link name="y_lock_link">
  <visual>
   <geometry>
    <box size="0.001 0.001 0.001"/>
   </geometry>
   <material name="levion_black"/>
   <origin rpy="0 0 0" xyz="0 0 0"/>
  </visual>
  <collision>
   <geometry>
    <box size="0.001 0.001 0.001"/>
   </geometry>
   <origin rpy="0 0 0" xyz="0 0 0"/>
  </collision>
  <inertial>
   <mass value="0.0001"/>
   <origin rpy="0 0 0" xyz="0 0 0"/>
   <inertia ixx="0.0001" ixy="0" ixz="0" iyy="0.0001" iyz="0" izz="0.0001"/>
  </inertial>
 </link>
 <joint name="y_lock_joint" type="prismatic">
  <origin rpy="0 0 0" xyz="0 0 0"/>
  <parent link="x_lock_link"/>
  <child link="y_lock_link"/>
  <axis xyz="0 1 0"/>
  <limit effort="10.0" lower="-10" upper="10" velocity="10"/>
 </joint>
 <!-- Base Join and Link-->
 <joint name="base_joint" type="revolute">
  <origin rpy="0 0 0" xyz="0 0 0.1"/>
  <parent link="y_lock_link"/>
  <child link="base_link"/>
  <axis xyz="0 0 1"/>
  <limit effort="10.0" lower="-10" upper="10" velocity="10"/>
  <!-- <dynamics damping="0.5" friction="0.0"/> -->
 </joint>
 <link name="base_link">
  <visual>
   <geometry>
    <mesh filename="package://pingu_description/mesh/base_link.stl" scale="1 1 1"/>
   </geometry>
   <material name="levion_black"/>
   <origin rpy="0 0 0" xyz="0 0 0"/>
  </visual>
  <collision>
   <geometry>
    <mesh filename="package://pingu_description/mesh/base_link.stl" scale="1 1 1"/>
   </geometry>
   <origin rpy="0 0 0" xyz="0 0 0"/>
   <!-- 0 0 0.3276 for box -->
  </collision>
  <inertial>
   <mass value="23.0"/>
   <origin rpy="0 0 0" xyz="0 0 0.3276"/>
   <inertia ixx="0.7" ixy="0" ixz="0" iyy="0.7" iyz="0" izz="0.5"/>
  </inertial>
 </link>
 <joint name="rw_base_joint" type="fixed">
  <origin rpy="0 0 0" xyz="0 0 .2875"/>
  <parent link="base_link"/>
  <child link="rw_base"/>
 </joint>
 <!-- Base Link -->
 <link name="rw_base">
  <collision>
   <origin rpy="0 0 0" xyz="0 0 0"/>
   <geometry>
    <mesh filename="package://pingu_description/mesh/rw_base.stl" scale="1 1 1"/>
   </geometry>
  </collision>
  <visual>
   <origin rpy="0 0 0.785" xyz="0 0 0"/>
   <geometry>
    <mesh filename="package://pingu_description/mesh/rw_base.stl" scale="1 1 1"/>
   </geometry>
   <material name="orange"/>
  </visual>
  <inertial>
   <origin rpy="0 0 0.785" xyz="0 0 0"/>
   <mass value="1.0"/>
   <inertia ixx="0.01" ixy="0.0" ixz="0.0" iyy="0.01" iyz="0.0" izz="0.01"/>
  </inertial>
 </link>
 <!-- Middle Link -->
 <link name="rw_rotor">
  <collision>
   <origin rpy="0 0 0" xyz="0 0 0"/>
   <geometry>
    <cylinder length="0.05" radius="0.1"/>
   </geometry>
  </collision>
  <visual>
   <origin rpy="0 0 0" xyz="0 0 0"/>
   <geometry>
    <cylinder length="0.05" radius="0.1"/>
   </geometry>
   <material name="orange"/>
  </visual>
  <inertial>
   <origin rpy="0 0 0" xyz="0 0 0"/>
   <mass value="2.0"/>
   <inertia ixx="0.06" ixy="0.0" ixz="0.0" iyy="0.06" iyz="0.0" izz="0.1"/>
  </inertial>
 </link>
 <joint name="rw_joint" type="revolute">
  <parent link="rw_base"/>
  <child link="rw_rotor"/>
  <origin rpy="0 0 0" xyz="0 0 0.05"/>
  <axis xyz="0 0 1"/>
  <limit effort="10.0" lower="-1e9" upper="1e9" velocity="100"/>
  <dynamics damping="0.5" friction="0.5"/>
 </joint>
 <joint name="left_base_joint" type="fixed">
  <origin rpy="0 0 0.785398163375" xyz="0.18384776309900003 0.18384776309900003 .3475"/>
  <parent link="base_link"/>
  <child link="left_link0"/>
 </joint>
 <link name="left_link0">
  <visual>
   <origin rpy="0 0 0" xyz="0 0 0"/>
   <geometry>
    <mesh filename="package://pingu_description/mesh/arm_link0.stl" scale="1 1 1"/>
   </geometry>
   <material name="levion_black"/>
  </visual>
  <collision>
   <origin rpy="0 0 0" xyz="0 0 0"/>
   <geometry>
    <mesh filename="package://pingu_description/mesh/arm_link0.stl" scale="1 1 1"/>
   </geometry>
  </collision>
  <inertial>
   <origin rpy="0 0 0" xyz="0 0 0"/>
   <mass value="0.5"/>
   <inertia ixx="0.0005" ixy="0.0" ixz="0.0" iyy="0.0005" iyz="0.0" izz="0.0005"/>
  </inertial>
 </link>
 <link name="left_link1">
  <visual>
   <origin rpy="0 0 0" xyz="0 0 0"/>
   <geometry>
    <mesh filename="package://pingu_description/mesh/arm_link1.stl" scale="1 1 1"/>
   </geometry>
   <material name="levion_black"/>
  </visual>
  <collision>
   <origin rpy="0 0 0" xyz="0 0 0"/>
   <geometry>
    <mesh filename="package://pingu_description/mesh/arm_link1.stl" scale="1 1 1"/>
   </geometry>
  </collision>
  <inertial>
   <origin rpy="0 0 0" xyz="0.05 0 0"/>
   <mass value="0.6"/>
   <inertia ixx="0.0006" ixy="0.0" ixz="0.0" iyy="0.0006" iyz="0.0" izz="0.0006"/>
  </inertial>
 </link>
 <link name="left_link2">
  <visual>
   <origin rpy="0 0 0" xyz="0 0 0"/>
   <geometry>
    <mesh filename="package://pingu_description/mesh/arm_link2.stl" scale="1 1 1"/>
   </geometry>
   <material name="levion_black"/>
  </visual>
  <collision>
   <origin rpy="0 0 0" xyz="0 0 0"/>
   <geometry>
    <mesh filename="package://pingu_description/mesh/arm_link2.stl" scale="1 1 1"/>
   </geometry>
  </collision>
  <inertial>
   <origin rpy="0 0 0" xyz="0 0 0"/>
   <mass value="0.1"/>
   <inertia ixx="0.0001" ixy="0.0" ixz="0.0" iyy="0.0001" iyz="0.0" izz="0.0001"/>
  </inertial>
 </link>
 <link name="left_tool_link">
  </link>
 <joint name="left_shoulder_joint" type="revolute">
  <origin rpy="0 0 0" xyz="0 0 0.0439"/>
  <parent link="left_link0"/>
  <child link="left_link1"/>
  <axis xyz="0 0 1"/>
  <limit effort="10" lower="-1.56079632675" upper="1.56079632675" velocity="10"/>
 </joint>
 <joint name="left_elbow_joint" type="revolute">
  <origin rpy="0 0 0" xyz="0.32 0 0.04685"/>
  <parent link="left_link1"/>
  <child link="left_link2"/>
  <axis xyz="0 0 1"/>
  <limit effort="10" lower="-2.6050000000000004" upper="-0.359" velocity="10"/>
 </joint>
 <joint name="left_tool_joint" type="fixed">
  <origin rpy="1.57079632675 0 1.57079632675" xyz=".255 0 0"/>
  <parent link="left_link2"/>
  <child link="left_tool_link"/>
 </joint>
 <joint name="right_base_joint" type="fixed">
  <origin rpy="0 0 -0.785398163375" xyz="0.18384776309900003 -0.18384776309900003 .3475"/>
  <parent link="base_link"/>
  <child link="right_link0"/>
 </joint>
 <link name="right_link0">
  <visual>
   <origin rpy="0 0 0" xyz="0 0 0"/>
   <geometry>
    <mesh filename="package://pingu_description/mesh/arm_link0.stl" scale="1 1 1"/>
   </geometry>
   <material name="levion_black"/>
  </visual>
  <collision>
   <origin rpy="0 0 0" xyz="0 0 0"/>
   <geometry>
    <mesh filename="package://pingu_description/mesh/arm_link0.stl" scale="1 1 1"/>
   </geometry>
  </collision>
  <inertial>
   <origin rpy="0 0 0" xyz="0 0 0"/>
   <mass value="0.5"/>
   <inertia ixx="0.0005" ixy="0.0" ixz="0.0" iyy="0.0005" iyz="0.0" izz="0.0005"/>
  </inertial>
 </link>
 <link name="right_link1">
  <visual>
   <origin rpy="0 0 0" xyz="0 0 0"/>
   <geometry>
    <mesh filename="package://pingu_description/mesh/arm_link1.stl" scale="1 1 1"/>
   </geometry>
   <material name="levion_black"/>
  </visual>
  <collision>
   <origin rpy="0 0 0" xyz="0 0 0"/>
   <geometry>
    <mesh filename="package://pingu_description/mesh/arm_link1.stl" scale="1 1 1"/>
   </geometry>
  </collision>
  <inertial>
   <origin rpy="0 0 0" xyz="0.05 0 0"/>
   <mass value="0.6"/>
   <inertia ixx="0.0006" ixy="0.0" ixz="0.0" iyy="0.0006" iyz="0.0" izz="0.0006"/>
  </inertial>
 </link>
 <link name="right_link2">
  <visual>
   <origin rpy="0 0 0" xyz="0 0 0"/>
   <geometry>
    <mesh filename="package://pingu_description/mesh/arm_link2.stl" scale="1 1 1"/>
   </geometry>
   <material name="levion_black"/>
  </visual>
  <collision>
   <origin rpy="0 0 0" xyz="0 0 0"/>
   <geometry>
    <mesh filename="package://pingu_description/mesh/arm_link2.stl" scale="1 1 1"/>
   </geometry>
  </collision>
  <inertial>
   <origin rpy="0 0 0" xyz="0 0 0"/>
   <mass value="0.1"/>
   <inertia ixx="0.0001" ixy="0.0" ixz="0.0" iyy="0.0001" iyz="0.0" izz="0.0001"/>
  </inertial>
 </link>
 <link name="right_tool_link">
  </link>
 <joint name="right_shoulder_joint" type="revolute">
  <origin rpy="0 0 0" xyz="0 0 0.0439"/>
  <parent link="right_link0"/>
  <child link="right_link1"/>
  <axis xyz="0 0 1"/>
  <limit effort="10" lower="-1.56079632675" upper="1.56079632675" velocity="10"/>
 </joint>
 <joint name="right_elbow_joint" type="revolute">
  <origin rpy="0 0 0" xyz="0.32 0 0.04685"/>
  <parent link="right_link1"/>
  <child link="right_link2"/>
  <axis xyz="0 0 1"/>
  <limit effort="10" lower="0.359" upper="2.6050000000000004" velocity="10"/>
 </joint>
 <joint name="right_tool_joint" type="fixed">
  <origin rpy="1.57079632675 0 1.57079632675" xyz=".255 0 0"/>
  <parent link="right_link2"/>
  <child link="right_tool_link"/>
 </joint>
</robot>
